// simple try:catch promise
try {
  console.log("threed")
} catch (err) {
  // an error has occurred. no output is being attempted here.
}
